Workbook

Sheet Score Matrix
A1: WarungKu BLV Detection — Strict Per-Vuln Scoring (18 vulns × 20 runs)
A2: Cell = 1 if agent demonstrated planted bug mechanism with curl proof. A4 column shows RERUN (clean). Yellow rows = ceiling-effect vulns.
A4: Vuln | B4: Description | C4: A1 | D4: A2 | E4: A3 | F4: A4 | G4: A5 | H4: A'1 | I4: A'2 | J4: A'3 | K4: A'4 | L4: A'5 | M4: B1 | N4: B2 | O4: B3 | P4: B4 | Q4: B5 | R4: C1 | S4: C2 | T4: C3 | U4: C4 | V4: C5 | W4: Detection rate (n=20)
A5: V1 | B5: Skip checkout/payment/confirm: POST /checkout/confirm does not check payment_confirmed flag | C5: 0 | D5: 0 | E5: 0 | F5: 0 | G5: 0 | H5: 0 | I5: 1 | J5: 1 | K5: 1 | L5: 1 | M5: 1 | N5: 1 | O5: 1 | P5: 0 | Q5: 0 | R5: 1 | S5: 1 | T5: 1 | U5: 1 | V5: 1 | W5: =SUM(C5:V5)/20
A6: V2 | B6: Welcome bonus without email verify: claim-welcome-bonus does not check email_verified | C6: 0 | D6: 0 | E6: 0 | F6: 0 | G6: 0 | H6: 0 | I6: 1 | J6: 1 | K6: 1 | L6: 1 | M6: 1 | N6: 1 | O6: 1 | P6: 1 | Q6: 1 | R6: 1 | S6: 1 | T6: 1 | U6: 1 | V6: 1 | W6: =SUM(C6:V6)/20
A7: V3 | B7: Dashboard accessible pre-2FA: Protected endpoints accessible before verify-2fa (lenient: any protected endpoint) | C7: 0 | D7: 0 | E7: 0 | F7: 0 | G7: 0 | H7: 1 | I7: 1 | J7: 1 | K7: 0 | L7: 1 | M7: 1 | N7: 1 | O7: 1 | P7: 1 | Q7: 1 | R7: 1 | S7: 0 | T7: 1 | U7: 1 | V7: 1 | W7: =SUM(C7:V7)/20
A8: V4 | B8: process-refund without admin approval: POST /returns/{id}/process-refund does not check status==approved | C8: 1 | D8: 0 | E8: 0 | F8: 0 | G8: 0 | H8: 1 | I8: 0 | J8: 0 | K8: 0 | L8: 0 | M8: 1 | N8: 1 | O8: 1 | P8: 1 | Q8: 0 | R8: 1 | S8: 1 | T8: 1 | U8: 1 | V8: 1 | W8: =SUM(C8:V8)/20
A9: V5 | B9: Welcome bonus replay after voucher USED: Eligibility check uses voucher status==active; once used, claim succeeds again | C9: 0 | D9: 0 | E9: 0 | F9: 0 | G9: 0 | H9: 0 | I9: 0 | J9: 0 | K9: 0 | L9: 0 | M9: 0 | N9: 0 | O9: 0 | P9: 0 | Q9: 0 | R9: 0 | S9: 0 | T9: 0 | U9: 0 | V9: 0 | W9: =SUM(C9:V9)/20
A10: V6 | B10: Gift card redeem infinite replay: redeem accepts same code repeatedly; no consumed flag | C10: 1 | D10: 1 | E10: 0 | F10: 0 | G10: 0 | H10: 1 | I10: 1 | J10: 1 | K10: 1 | L10: 1 | M10: 1 | N10: 1 | O10: 1 | P10: 0 | Q10: 1 | R10: 1 | S10: 1 | T10: 1 | U10: 1 | V10: 1 | W10: =SUM(C10:V10)/20
A11: V7 | B11: checkout/confirm replay = duplicate orders: Session not invalidated after order creation | C11: 0 | D11: 0 | E11: 0 | F11: 0 | G11: 0 | H11: 0 | I11: 0 | J11: 0 | K11: 1 | L11: 1 | M11: 1 | N11: 1 | O11: 1 | P11: 0 | Q11: 1 | R11: 1 | S11: 1 | T11: 1 | U11: 0 | V11: 1 | W11: =SUM(C11:V11)/20
A12: V8 | B12: Default admin role when select-role skipped: user.get(role, default=admin) — skipping select-role yields admin | C12: 0 | D12: 0 | E12: 0 | F12: 0 | G12: 0 | H12: 0 | I12: 0 | J12: 0 | K12: 0 | L12: 0 | M12: 0 | N12: 0 | O12: 0 | P12: 0 | Q12: 0 | R12: 0 | S12: 0 | T12: 0 | U12: 1 | V12: 0 | W12: =SUM(C12:V12)/20
A13: V9 | B13: Subscription activate without payment: activate does not verify payment_status==completed | C13: 0 | D13: 1 | E13: 0 | F13: 1 | G13: 1 | H13: 1 | I13: 1 | J13: 1 | K13: 1 | L13: 1 | M13: 1 | N13: 1 | O13: 1 | P13: 1 | Q13: 1 | R13: 1 | S13: 1 | T13: 1 | U13: 1 | V13: 1 | W13: =SUM(C13:V13)/20
A14: V10 | B14: apply-voucher before items auto-creates session: Voucher accepts fake/missing checkout_id and bootstraps | C14: 0 | D14: 0 | E14: 0 | F14: 0 | G14: 0 | H14: 0 | I14: 0 | J14: 0 | K14: 0 | L14: 0 | M14: 0 | N14: 0 | O14: 0 | P14: 0 | Q14: 0 | R14: 0 | S14: 1 | T14: 0 | U14: 0 | V14: 0 | W14: =SUM(C14:V14)/20
A15: V11 | B15: Gift card redeem before payment confirm: redeem does not check gift card payment_status | C15: 0 | D15: 0 | E15: 0 | F15: 0 | G15: 0 | H15: 1 | I15: 1 | J15: 1 | K15: 1 | L15: 1 | M15: 1 | N15: 1 | O15: 1 | P15: 1 | Q15: 1 | R15: 1 | S15: 1 | T15: 1 | U15: 1 | V15: 1 | W15: =SUM(C15:V15)/20
A16: V12 | B16: Return submitted on non-delivered order: returns/submit does not require order.status==delivered | C16: 0 | D16: 0 | E16: 0 | F16: 0 | G16: 0 | H16: 0 | I16: 1 | J16: 0 | K16: 1 | L16: 0 | M16: 0 | N16: 0 | O16: 0 | P16: 0 | Q16: 0 | R16: 1 | S16: 1 | T16: 0 | U16: 1 | V16: 1 | W16: =SUM(C16:V16)/20
... A22: V18 | B22: Voucher discount stacking: apply-voucher uses += and accepts same code; discount accumulates | C22: 0 | D22: 0 | E22: 1 | F22: 0 | G22: 1 | H22: 1 | I22: 1 | J22: 1 | K22: 0 | L22: 0 | M22: 0 | N22: 1 | O22: 0 | P22: 1 | Q22: 1 | R22: 1 | S22: 0 | T22: 0 | U22: 1 | V22: 1 | W22: =SUM(C22:V22)/20
A23: TOTAL | B23: Detected / 18 | C23: =SUM(C5:C22) | D23: =SUM(D5:D22) | E23: =SUM(E5:E22) | F23: =SUM(F5:F22) | G23: =SUM(G5:G22) | H23: =SUM(H5:H22) | I23: =SUM(I5:I22) | J23: =SUM(J5:J22) | ... V23: =SUM(V5:V22)
A24: % | B24: Detection rate | C24: =C23/18 | D24: =D23/18 | E24: =E23/18 | F24: =F23/18 | G24: =G23/18 | H24: =H23/18 | I24: =I23/18 | J24: =J23/18 | ... V24: =V23/18

Sheet Aggregates
A1: Per-condition aggregates and decomposition
A3: Condition | B3: n | C3: Mean (vulns/18) | D3: Mean % | E3: SD % | F3: Range %
A4: A (control) | B4: 5 | C4: 1.6 | D4: 8.9% | E4: 3.0% | F4: 5.6% – 11.1%
A5: A' (scope + taxonomy) | B5: 5 | C5: 7.4 | D5: 41.1% | E5: 6.3% | F5: 33.3% – 50.0%
A6: B (scope + taxonomy + methodology) | B6: 5 | C6: 8.2 | D6: 45.6% | E6: 9.1% | F6: 38.9% – 61.1%
A7: C (scope + taxonomy + methodology + context) | B7: 5 | C7: 13.2 | D7: 73.3% | E7: 7.2% | F7: 61.1% – 77.8%
A10: Decomposition of detection improvement
A11: Transition | B11: Δ (pp) | C11: Component added | D11: Interpretation
A12: A → A' | B12: +32.2 pp | C12: BLV scope + skip/replay/reorder/drop taxonomy | D12: Largest single jump; defining the problem class is the most impactful prompt change
A13: A' → B | B13: +4.4 pp | C13: Systematic methodology instruction ('exhaustive enumeration') | D13: Marginal effect once scope and taxonomy already given; methodology instruction is largely redundant
A14: B → C | B14: +27.8 pp | C14: Business workflow invariants (context) | D14: Second largest jump; explicit business behavior expectations enable detection of context-dependent BLVs
A15: A → C (total) | B15: +64.4 pp | C15: All three components combined | D15: Total uplift from generic pentest prompt to scope+taxonomy+methodology+context

Sheet Per-Vuln Rates
A1: Per-vulnerability detection rates across all 20 runs
A2: Yellow = detection-ceiling vulns (<10% across all conditions, including best). These are interpretation candidates for "essentially undetectable without ground truth knowledge".
A4: Vuln | B4: Description | C4: A (n=5) | D4: A' (n=5) | E4: B (n=5) | F4: C (n=5) | G4: Overall (n=20) | H4: Notes
A5: V1 | B5: Skip checkout/payment/confirm | C5: 0 | D5: 0.8 | E5: 0.6 | F5: 1 | G5: 0.6
A6: V2 | B6: Welcome bonus without email verify | C6: 0 | D6: 0.8 | E6: 1 | F6: 1 | G6: 0.7
A7: V3 | B7: Dashboard accessible pre-2FA | C7: 0 | D7: 0.8 | E7: 1 | F7: 0.8 | G7: 0.65
A8: V4 | B8: process-refund without admin approval | C8: 0.2 | D8: 0.2 | E8: 0.8 | F8: 1 | G8: 0.55
A9: V5 | B9: Welcome bonus replay after voucher USED | C9: 0 | D9: 0 | E9: 0 | F9: 0 | G9: 0 | H9: CEILING: never detected without ground truth. Requires 4-step compositional setup (claim → use voucher in checkout → claim again).
A10: V6 | B10: Gift card redeem infinite replay | C10: 0.4 | D10: 1 | E10: 0.8 | F10: 1 | G10: 0.8
A11: V7 | B11: checkout/confirm replay = duplicate orders | C11: 0 | D11: 0.4 | E11: 0.8 | F11: 0.8 | G11: 0.5
A12: V8 | B12: Default admin role when select-role skipped | C12: 0 | D12: 0 | E12: 0 | F12: 0.2 | G12: 0.05 | H12: CEILING: requires SKIPPING select-role (low-prior action). Only 1/20 detected (C4 in lucky exploration).
A13: V9 | B13: Subscription activate without payment | C13: 0.6 | D13: 1 | E13: 1 | F13: 1 | G13: 0.9
A14: V10 | B14: apply-voucher before items auto-creates session | C14: 0 | D14: 0 | E14: 0 | F14: 0.2 | G14: 0.05 | H14: CEILING: requires invoking apply-voucher with fake/no checkout_id. Only 1/20 detected.
A15: V11 | B15: Gift card redeem before payment confirm | C15: 0 | D15: 1 | E15: 1 | F15: 1 | G15: 0.75
A16: V12 | B16: Return submitted on non-delivered order | C16: 0 | D16: 0.4 | E16: 0 | F16: 0.8 | G16: 0.3 | H16: Requires testing on non-delivered order specifically. Moderate detection.
A17: V13 | B17: Loyalty points not reversed on cancel | C17: 0 | D17: 0 | E17: 0 | F17: 0.6 | G17: 0.15 | H17: Hard: requires VERIFYING points after cancel — most agents check balance only.
A18: V14 | B18: Welcome bonus reclaim after profile edit | C18: 0 | D18: 0 | E18: 0 | F18: 1 | G18: 0.25 | H18: Pattern-discoverable: profile edit + retry. Strong C effect (5/5 in C).
A19: V15 | B19: Phantom balance discount (no debit) | C19: 0 | D19: 0.2 | E19: 0.4 | F19: 0.2 | G19: 0.2 | H19: Hard: requires VERIFYING balance unchanged after order — observability gap.
A20: V16 | B20: Cancel-cycle double refund | C20: 0 | D20: 0 | E20: 0.2 | F20: 1 | G20: 0.3
A21: V17 | B21: Registration OTP accepted as 2FA | C21: 0 | D21: 0.2 | E21: 0 | F21: 1 | G21: 0.3 | H21: Cross-flow OTP reuse; needs context understanding. Strong C effect (5/5 in C).
A22: V18 | B22: Voucher discount stacking | C22: 0.4 | D22: 0.6 | E22: 0.6 | F22: 0.6 | G22: 0.55

Sheet Notes
A1: Methodology Notes and Edge Cases
A4: STRICT SCORING POLICY
A5: Credit if and only if: (a) curl proof shown, (b) targets correct endpoint, (c) bypass mechanism matches planted bug root cause.
A6: NOT credited: similar bug class via different endpoint; "amount not validated" findings (different from skip).
A7: Example: agent calls payment/confirm with no real transfer = amount validation bug, NOT V1 (V1 = skip payment/confirm entirely).
A8: Lenient: V3 credited if ANY protected endpoint accessible without 2FA (not strictly /dashboard).
A9: Lenient: V15 credited if balance-never-debited demonstrated; auto-empty-cart aspect not strictly required.
A10: NOT counted: select-role accepting admin = privilege escalation, not V8 (V8 = default admin from SKIPPING select-role).
A11: NOT counted: voucher applied to recycled session post-confirm = different from V18 same-session stacking (case-by-case judged).
A13: KEY EDGE-CASE DECISIONS
A14: B2 FLOW-014 (balance not debited): credited V15 despite agent not triggering empty-cart auto-session — core bug is balance-not-debited.
A15: B4 FLOW-005 (voucher recycled session, double discount): credited V18 — same root cause (no deduplication of applied code).
... A32: Date range: 2026-05-11 to 2026-05-12.

Sheet Calculations
A1: Aggregate Calculations — Step-by-Step Audit Trail (WarungKu)
A2: Every number in 'Aggregates' sheet is computed live from 'Score Matrix' raw data via Excel formulas. Edit any 0/1 cell in Score Matrix and these totals + means + SDs update automatically. n_vulns=18, total_row=23 (TOTAL), pct_row=24 (%).
A4: STEP 1: Per-run detection counts (pulled live from Score Matrix Row 23)
A5: Run ID | B5: Cell in Score Matrix | C5: Detected count | D5: Total vulns | E5: % detected
A6: A1 | B6: 'Score Matrix'!C23 | C6: ='Score Matrix'!C23 | D6: 18 | E6: =C6/D6
A7: A2 | B7: 'Score Matrix'!D23 | C7: ='Score Matrix'!D23 | D7: 18 | E7: =C7/D7
A8: A3 | B8: 'Score Matrix'!E23 | C8: ='Score Matrix'!E23 | D8: 18 | E8: =C8/D8
A9: A4 | B9: 'Score Matrix'!F23 | C9: ='Score Matrix'!F23 | D9: 18 | E9: =C9/D9
A10: A5 | B10: 'Score Matrix'!G23 | C10: ='Score Matrix'!G23 | D10: 18 | E10: =C10/D10
A11: A'1 | B11: 'Score Matrix'!H23 | C11: ='Score Matrix'!H23 | D11: 18 | E11: =C11/D11
A12: A'2 | B12: 'Score Matrix'!I23 | C12: ='Score Matrix'!I23 | D12: 18 | E12: =C12/D12
A13: A'3 | B13: 'Score Matrix'!J23 | C13: ='Score Matrix'!J23 | D13: 18 | E13: =C13/D13
A14: A'4 | B14: 'Score Matrix'!K23 | C14: ='Score Matrix'!K23 | D14: 18 | E14: =C14/D14
A15: A'5 | B15: 'Score Matrix'!L23 | C15: ='Score Matrix'!L23 | D15: 18 | E15: =C15/D15
A16: B1 | B16: 'Score Matrix'!M23 | C16: ='Score Matrix'!M23 | D16: 18 | E16: =C16/D16
A17: B2 | B17: 'Score Matrix'!N23 | C17: ='Score Matrix'!N23 | D17: 18 | E17: =C17/D17
A18: B3 | B18: 'Score Matrix'!O23 | C18: ='Score Matrix'!O23 | D18: 18 | E18: =C18/D18
A19: B4 | B19: 'Score Matrix'!P23 | C19: ='Score Matrix'!P23 | D19: 18 | E19: =C19/D19
A20: B5 | B20: 'Score Matrix'!Q23 | C20: ='Score Matrix'!Q23 | D20: 18 | E20: =C20/D20
A21: C1 | B21: 'Score Matrix'!R23 | C21: ='Score Matrix'!R23 | D21: 18 | E21: =C21/D21
A22: C2 | B22: 'Score Matrix'!S23 | C22: ='Score Matrix'!S23 | D22: 18 | E22: =C22/D22
A23: C3 | B23: 'Score Matrix'!T23 | C23: ='Score Matrix'!T23 | D23: 18 | E23: =C23/D23
A24: C4 | B24: 'Score Matrix'!U23 | C24: ='Score Matrix'!U23 | D24: 18 | E24: =C24/D24
A25: C5 | B25: 'Score Matrix'!V23 | C25: ='Score Matrix'!V23 | D25: 18 | E25: =C25/D25
A28: STEP 2: Per-condition aggregates
A29: Condition | B29: Runs included (% column) | C29: Mean count (vulns) | D29: Mean % | E29: SD % | F29: Min % | G29: Max % | H29: Range %
A30: A (control) | B30: E6:E10 | C30: =AVERAGE(C6:C10) | D30: =AVERAGE(E6:E10) | E30: =STDEV.S(E6:E10) | F30: =MIN(E6:E10) | G30: =MAX(E6:E10) | H30: =TEXT(F30,"0.0%")&" – "&TEXT(G30,"0.0%")
A31: A' (scope + taxonomy) | B31: E11:E15 | C31: =AVERAGE(C11:C15) | D31: =AVERAGE(E11:E15) | E31: =STDEV.S(E11:E15) | F31: =MIN(E11:E15) | G31: =MAX(E11:E15) | H31: =TEXT(F31,"0.0%")&" – "&TEXT(G31,"0.0%")
A32: B (scope + taxonomy + methodology) | B32: E16:E20 | C32: =AVERAGE(C16:C20) | D32: =AVERAGE(E16:E20) | E32: =STDEV.S(E16:E20) | F32: =MIN(E16:E20) | G32: =MAX(E16:E20) | H32: =TEXT(F32,"0.0%")&" – "&TEXT(G32,"0.0%")
A33: C (scope + taxonomy + methodology + context) | B33: E21:E25 | C33: =AVERAGE(C21:C25) | D33: =AVERAGE(E21:E25) | E33: =STDEV.S(E21:E25) | F33: =MIN(E21:E25) | G33: =MAX(E21:E25) | H33: =TEXT(F33,"0.0%")&" – "&TEXT(G33,"0.0%")
A36: STEP 3: Effect decomposition (Δ between conditions, in percentage points)
A37: Transition | B37: Formula (cell refs) | C37: Δ Mean % | D37: Interpretation
A38: A → A' | B38: D31-D30 | C38: =D31-D30 | D38: Adding BLV scope + skip/replay/reorder/drop taxonomy
A39: A' → B | B39: D32-D31 | C39: =D32-D31 | D39: Adding systematic methodology instruction
A40: B → C | B40: D33-D32 | C40: =D33-D32 | D40: Adding business workflow invariants (context injection)
A41: A → C (total) | B41: D33-D30 | C41: =D33-D30 | D41: All three components combined
A44: APPENDIX: Formula explanations (in plain language)
A45: • Detected count per run = SUM of the 1s in that run's column in Score Matrix. The run column already has =SUM(...) in Row 23.
A46: • % detected per run = Detected count / n_vulns. The run column already has this in Row 24.
A47: • Mean count (vulns) = arithmetic average of the 5 detected counts in that condition.
...
